2018-11-02 10:14:35,508 - base.py - [line:93] - WARNING - Not Found: /favicon.ico
2018-11-02 10:15:32,832 - base.py - [line:93] - WARNING - Not Found: /favicon.ico
2018-11-05 08:55:48,815 - base.py - [line:93] - WARNING - Not Found: /favicon.ico
2018-11-05 10:11:28,518 - base.py - [line:93] - WARNING - Not Found: /favicon.ico
2018-11-05 10:11:44,215 - base.py - [line:93] - WARNING - Not Found: /
2018-11-05 10:11:53,026 - base.py - [line:93] - WARNING - Not Found: /admin
2018-11-05 10:12:21,296 - base.py - [line:93] - WARNING - Not Found: /admin/
2018-11-05 10:12:21,312 - base.py - [line:93] - WARNING - Not Found: /favicon.ico
2018-11-05 10:13:20,031 - exception.py - [line:118] - ERROR - Internal Server Error: /admin/
Traceback (most recent call last):
  File "F:\ANACONDA\lib\site-packages\django\core\handlers\exception.py", line 35, in inner
    response = get_response(request)
  File "F:\ANACONDA\lib\site-packages\django\core\handlers\base.py", line 128, in _get_response
    response = self.process_exception_by_middleware(e, request)
  File "F:\ANACONDA\lib\site-packages\django\core\handlers\base.py", line 126, in _get_response
    response = wrapped_callback(request, *callback_args, **callback_kwargs)
  File "F:\ANACONDA\lib\site-packages\django\contrib\admin\sites.py", line 241, in wrapper
    return self.admin_view(view, cacheable)(*args, **kwargs)
  File "F:\ANACONDA\lib\site-packages\django\utils\decorators.py", line 142, in _wrapped_view
    response = view_func(request, *args, **kwargs)
  File "F:\ANACONDA\lib\site-packages\django\views\decorators\cache.py", line 44, in _wrapped_view_func
    response = view_func(request, *args, **kwargs)
  File "F:\ANACONDA\lib\site-packages\django\contrib\admin\sites.py", line 212, in inner
    if not self.has_permission(request):
  File "F:\ANACONDA\lib\site-packages\django\contrib\admin\sites.py", line 186, in has_permission
    return request.user.is_active and request.user.is_staff
AttributeError: 'WSGIRequest' object has no attribute 'user'
2018-11-05 10:13:45,713 - exception.py - [line:118] - ERROR - Internal Server Error: /admin/
Traceback (most recent call last):
  File "F:\ANACONDA\lib\site-packages\django\core\handlers\exception.py", line 35, in inner
    response = get_response(request)
  File "F:\ANACONDA\lib\site-packages\django\core\handlers\base.py", line 128, in _get_response
    response = self.process_exception_by_middleware(e, request)
  File "F:\ANACONDA\lib\site-packages\django\core\handlers\base.py", line 126, in _get_response
    response = wrapped_callback(request, *callback_args, **callback_kwargs)
  File "F:\ANACONDA\lib\site-packages\django\contrib\admin\sites.py", line 241, in wrapper
    return self.admin_view(view, cacheable)(*args, **kwargs)
  File "F:\ANACONDA\lib\site-packages\django\utils\decorators.py", line 142, in _wrapped_view
    response = view_func(request, *args, **kwargs)
  File "F:\ANACONDA\lib\site-packages\django\views\decorators\cache.py", line 44, in _wrapped_view_func
    response = view_func(request, *args, **kwargs)
  File "F:\ANACONDA\lib\site-packages\django\contrib\admin\sites.py", line 212, in inner
    if not self.has_permission(request):
  File "F:\ANACONDA\lib\site-packages\django\contrib\admin\sites.py", line 186, in has_permission
    return request.user.is_active and request.user.is_staff
AttributeError: 'WSGIRequest' object has no attribute 'user'
2018-11-05 10:13:46,222 - exception.py - [line:118] - ERROR - Internal Server Error: /admin/
Traceback (most recent call last):
  File "F:\ANACONDA\lib\site-packages\django\core\handlers\exception.py", line 35, in inner
    response = get_response(request)
  File "F:\ANACONDA\lib\site-packages\django\core\handlers\base.py", line 128, in _get_response
    response = self.process_exception_by_middleware(e, request)
  File "F:\ANACONDA\lib\site-packages\django\core\handlers\base.py", line 126, in _get_response
    response = wrapped_callback(request, *callback_args, **callback_kwargs)
  File "F:\ANACONDA\lib\site-packages\django\contrib\admin\sites.py", line 241, in wrapper
    return self.admin_view(view, cacheable)(*args, **kwargs)
  File "F:\ANACONDA\lib\site-packages\django\utils\decorators.py", line 142, in _wrapped_view
    response = view_func(request, *args, **kwargs)
  File "F:\ANACONDA\lib\site-packages\django\views\decorators\cache.py", line 44, in _wrapped_view_func
    response = view_func(request, *args, **kwargs)
  File "F:\ANACONDA\lib\site-packages\django\contrib\admin\sites.py", line 212, in inner
    if not self.has_permission(request):
  File "F:\ANACONDA\lib\site-packages\django\contrib\admin\sites.py", line 186, in has_permission
    return request.user.is_active and request.user.is_staff
AttributeError: 'WSGIRequest' object has no attribute 'user'
2018-11-05 10:13:46,473 - exception.py - [line:118] - ERROR - Internal Server Error: /admin/
Traceback (most recent call last):
  File "F:\ANACONDA\lib\site-packages\django\core\handlers\exception.py", line 35, in inner
    response = get_response(request)
  File "F:\ANACONDA\lib\site-packages\django\core\handlers\base.py", line 128, in _get_response
    response = self.process_exception_by_middleware(e, request)
  File "F:\ANACONDA\lib\site-packages\django\core\handlers\base.py", line 126, in _get_response
    response = wrapped_callback(request, *callback_args, **callback_kwargs)
  File "F:\ANACONDA\lib\site-packages\django\contrib\admin\sites.py", line 241, in wrapper
    return self.admin_view(view, cacheable)(*args, **kwargs)
  File "F:\ANACONDA\lib\site-packages\django\utils\decorators.py", line 142, in _wrapped_view
    response = view_func(request, *args, **kwargs)
  File "F:\ANACONDA\lib\site-packages\django\views\decorators\cache.py", line 44, in _wrapped_view_func
    response = view_func(request, *args, **kwargs)
  File "F:\ANACONDA\lib\site-packages\django\contrib\admin\sites.py", line 212, in inner
    if not self.has_permission(request):
  File "F:\ANACONDA\lib\site-packages\django\contrib\admin\sites.py", line 186, in has_permission
    return request.user.is_active and request.user.is_staff
AttributeError: 'WSGIRequest' object has no attribute 'user'
2018-11-05 10:13:46,652 - exception.py - [line:118] - ERROR - Internal Server Error: /admin/
Traceback (most recent call last):
  File "F:\ANACONDA\lib\site-packages\django\core\handlers\exception.py", line 35, in inner
    response = get_response(request)
  File "F:\ANACONDA\lib\site-packages\django\core\handlers\base.py", line 128, in _get_response
    response = self.process_exception_by_middleware(e, request)
  File "F:\ANACONDA\lib\site-packages\django\core\handlers\base.py", line 126, in _get_response
    response = wrapped_callback(request, *callback_args, **callback_kwargs)
  File "F:\ANACONDA\lib\site-packages\django\contrib\admin\sites.py", line 241, in wrapper
    return self.admin_view(view, cacheable)(*args, **kwargs)
  File "F:\ANACONDA\lib\site-packages\django\utils\decorators.py", line 142, in _wrapped_view
    response = view_func(request, *args, **kwargs)
  File "F:\ANACONDA\lib\site-packages\django\views\decorators\cache.py", line 44, in _wrapped_view_func
    response = view_func(request, *args, **kwargs)
  File "F:\ANACONDA\lib\site-packages\django\contrib\admin\sites.py", line 212, in inner
    if not self.has_permission(request):
  File "F:\ANACONDA\lib\site-packages\django\contrib\admin\sites.py", line 186, in has_permission
    return request.user.is_active and request.user.is_staff
AttributeError: 'WSGIRequest' object has no attribute 'user'
2018-11-05 10:13:46,843 - exception.py - [line:118] - ERROR - Internal Server Error: /admin/
Traceback (most recent call last):
  File "F:\ANACONDA\lib\site-packages\django\core\handlers\exception.py", line 35, in inner
    response = get_response(request)
  File "F:\ANACONDA\lib\site-packages\django\core\handlers\base.py", line 128, in _get_response
    response = self.process_exception_by_middleware(e, request)
  File "F:\ANACONDA\lib\site-packages\django\core\handlers\base.py", line 126, in _get_response
    response = wrapped_callback(request, *callback_args, **callback_kwargs)
  File "F:\ANACONDA\lib\site-packages\django\contrib\admin\sites.py", line 241, in wrapper
    return self.admin_view(view, cacheable)(*args, **kwargs)
  File "F:\ANACONDA\lib\site-packages\django\utils\decorators.py", line 142, in _wrapped_view
    response = view_func(request, *args, **kwargs)
  File "F:\ANACONDA\lib\site-packages\django\views\decorators\cache.py", line 44, in _wrapped_view_func
    response = view_func(request, *args, **kwargs)
  File "F:\ANACONDA\lib\site-packages\django\contrib\admin\sites.py", line 212, in inner
    if not self.has_permission(request):
  File "F:\ANACONDA\lib\site-packages\django\contrib\admin\sites.py", line 186, in has_permission
    return request.user.is_active and request.user.is_staff
AttributeError: 'WSGIRequest' object has no attribute 'user'
2018-11-05 10:14:18,056 - exception.py - [line:118] - ERROR - Internal Server Error: /admin/
Traceback (most recent call last):
  File "F:\ANACONDA\lib\site-packages\django\core\handlers\exception.py", line 35, in inner
    response = get_response(request)
  File "F:\ANACONDA\lib\site-packages\django\core\handlers\base.py", line 128, in _get_response
    response = self.process_exception_by_middleware(e, request)
  File "F:\ANACONDA\lib\site-packages\django\core\handlers\base.py", line 126, in _get_response
    response = wrapped_callback(request, *callback_args, **callback_kwargs)
  File "F:\ANACONDA\lib\site-packages\django\contrib\admin\sites.py", line 241, in wrapper
    return self.admin_view(view, cacheable)(*args, **kwargs)
  File "F:\ANACONDA\lib\site-packages\django\utils\decorators.py", line 142, in _wrapped_view
    response = view_func(request, *args, **kwargs)
  File "F:\ANACONDA\lib\site-packages\django\views\decorators\cache.py", line 44, in _wrapped_view_func
    response = view_func(request, *args, **kwargs)
  File "F:\ANACONDA\lib\site-packages\django\contrib\admin\sites.py", line 212, in inner
    if not self.has_permission(request):
  File "F:\ANACONDA\lib\site-packages\django\contrib\admin\sites.py", line 186, in has_permission
    return request.user.is_active and request.user.is_staff
AttributeError: 'WSGIRequest' object has no attribute 'user'
2018-11-05 10:16:00,930 - exception.py - [line:118] - ERROR - Internal Server Error: /admin/
Traceback (most recent call last):
  File "F:\ANACONDA\lib\site-packages\django\core\handlers\exception.py", line 35, in inner
    response = get_response(request)
  File "F:\ANACONDA\lib\site-packages\django\core\handlers\base.py", line 128, in _get_response
    response = self.process_exception_by_middleware(e, request)
  File "F:\ANACONDA\lib\site-packages\django\core\handlers\base.py", line 126, in _get_response
    response = wrapped_callback(request, *callback_args, **callback_kwargs)
  File "F:\ANACONDA\lib\site-packages\django\contrib\admin\sites.py", line 241, in wrapper
    return self.admin_view(view, cacheable)(*args, **kwargs)
  File "F:\ANACONDA\lib\site-packages\django\utils\decorators.py", line 142, in _wrapped_view
    response = view_func(request, *args, **kwargs)
  File "F:\ANACONDA\lib\site-packages\django\views\decorators\cache.py", line 44, in _wrapped_view_func
    response = view_func(request, *args, **kwargs)
  File "F:\ANACONDA\lib\site-packages\django\contrib\admin\sites.py", line 212, in inner
    if not self.has_permission(request):
  File "F:\ANACONDA\lib\site-packages\django\contrib\admin\sites.py", line 186, in has_permission
    return request.user.is_active and request.user.is_staff
AttributeError: 'WSGIRequest' object has no attribute 'user'
2018-11-05 10:18:07,953 - exception.py - [line:118] - ERROR - Internal Server Error: /admin/
Traceback (most recent call last):
  File "F:\ANACONDA\lib\site-packages\django\core\handlers\exception.py", line 35, in inner
    response = get_response(request)
  File "F:\ANACONDA\lib\site-packages\django\core\handlers\base.py", line 128, in _get_response
    response = self.process_exception_by_middleware(e, request)
  File "F:\ANACONDA\lib\site-packages\django\core\handlers\base.py", line 126, in _get_response
    response = wrapped_callback(request, *callback_args, **callback_kwargs)
  File "F:\ANACONDA\lib\site-packages\django\contrib\admin\sites.py", line 241, in wrapper
    return self.admin_view(view, cacheable)(*args, **kwargs)
  File "F:\ANACONDA\lib\site-packages\django\utils\decorators.py", line 142, in _wrapped_view
    response = view_func(request, *args, **kwargs)
  File "F:\ANACONDA\lib\site-packages\django\views\decorators\cache.py", line 44, in _wrapped_view_func
    response = view_func(request, *args, **kwargs)
  File "F:\ANACONDA\lib\site-packages\django\contrib\admin\sites.py", line 212, in inner
    if not self.has_permission(request):
  File "F:\ANACONDA\lib\site-packages\django\contrib\admin\sites.py", line 186, in has_permission
    return request.user.is_active and request.user.is_staff
AttributeError: 'WSGIRequest' object has no attribute 'user'
2018-11-12 11:46:50,203 - exception.py - [line:118] - ERROR - Internal Server Error: /getOperate
Traceback (most recent call last):
  File "F:\ANACONDA\lib\site-packages\django\core\handlers\exception.py", line 35, in inner
    response = get_response(request)
  File "F:\ANACONDA\lib\site-packages\django\core\handlers\base.py", line 128, in _get_response
    response = self.process_exception_by_middleware(e, request)
  File "F:\ANACONDA\lib\site-packages\django\core\handlers\base.py", line 126, in _get_response
    response = wrapped_callback(request, *callback_args, **callback_kwargs)
  File "H:\program\proj_v1.0\proj\controller\Interface.py", line 119, in getOperate
    user_name = i[4]
IndexError: tuple index out of range
2018-11-12 11:52:04,781 - exception.py - [line:118] - ERROR - Internal Server Error: /getOperate
Traceback (most recent call last):
  File "F:\ANACONDA\lib\site-packages\django\core\handlers\exception.py", line 35, in inner
    response = get_response(request)
  File "F:\ANACONDA\lib\site-packages\django\core\handlers\base.py", line 128, in _get_response
    response = self.process_exception_by_middleware(e, request)
  File "F:\ANACONDA\lib\site-packages\django\core\handlers\base.py", line 126, in _get_response
    response = wrapped_callback(request, *callback_args, **callback_kwargs)
  File "H:\program\proj_v1.0\proj\controller\Interface.py", line 119, in getOperate
    user_name = i[4]
IndexError: tuple index out of range
2018-11-12 11:54:00,415 - base.py - [line:93] - WARNING - Not Found: /favicon.ico
